Workbook

Sheet Instructions
B2: SUSTAINABILITY DATA READINESS SCORECARD
B4: WHAT THIS TOOL DOES
B5: This scorecard evaluates your capability to respond to buyer sustainability
B6: data requests across 12 common requirement categories. You'll get:
B8: • Overall readiness score (0-100%)
B9: • Category-by-category breakdown
B10: • Auto-calculated response readiness for each item
B12: HOW TO COMPLETE THE ASSESSMENT
B14: Step 1: Go to the 'Assessment' tab
B16: Step 2: For each item, answer THREE questions:
B18: DATA CONFIDENCE - How confident are you in this data?
B19: 0 = No data (can't provide anything)
... B48: © Ecosystems United 2025 | All Rights Reserved

Sheet Assessment
B1: SUSTAINABILITY DATA READINESS ASSESSMENT
B2: Complete all 12 categories below using the dropdown menus
B4: Category / Sub-requirement | C4: Data Confidence | D4: Methodology Documented? | E4: Source Records Available? | F4: Response Ready | G4: Score
C5: How confident are you in this data? | D5: Do you have docs explaining HOW you measure this? | E5: Do you have the underlying records? | F5: (Auto-calculated)
B7: 1. CARBON FOOTPRINT DATA
B8: Scope 1 emissions (direct operational) | F8: =IF(OR(C8="",C8="N/A"),"", IF(AND(VALUE(LEFT(C8,1))>=3,D8="Yes",E8="Yes"),"✓ Ready", IF(AND(VALUE(LEFT(C8,1))>=3,OR(D8="Yes",E8="Yes")),"⚠ Likely", IF(AND(VALUE(LEFT(C8,1))>=2,D8="Yes",E8="Yes"),"⚠ Partial", IF(OR(VALUE(LEFT(C8,1))<=1,AND(D8="No",E8="No")),"✗ Not Ready","⚠ Weak"))))) | G8: =IF(OR(C8="",C8="N/A"),"", VALUE(LEFT(C8,1))*(IF(D8="Yes",0.5,IF(D8="Partial",0.25,0))+IF(E8="Yes",0.5,IF(E8="Partial",0.25,0))))
B9: Scope 2 emissions (purchased electricity/energy) | F9: =IF(OR(C9="",C9="N/A"),"", IF(AND(VALUE(LEFT(C9,1))>=3,D9="Yes",E9="Yes"),"✓ Ready", IF(AND(VALUE(LEFT(C9,1))>=3,OR(D9="Yes",E9="Yes")),"⚠ Likely", IF(AND(VALUE(LEFT(C9,1))>=2,D9="Yes",E9="Yes"),"⚠ Partial", IF(OR(VALUE(LEFT(C9,1))<=1,AND(D9="No",E9="No")),"✗ Not Ready","⚠ Weak"))))) | G9: =IF(OR(C9="",C9="N/A"),"", VALUE(LEFT(C9,1))*(IF(D9="Yes",0.5,IF(D9="Partial",0.25,0))+IF(E9="Yes",0.5,IF(E9="Partial",0.25,0))))
B10: Scope 3 upstream (if tracked) | F10: =IF(OR(C10="",C10="N/A"),"", IF(AND(VALUE(LEFT(C10,1))>=3,D10="Yes",E10="Yes"),"✓ Ready", IF(AND(VALUE(LEFT(C10,1))>=3,OR(D10="Yes",E10="Yes")),"⚠ Likely", IF(AND(VALUE(LEFT(C10,1))>=2,D10="Yes",E10="Yes"),"⚠ Partial", IF(OR(VALUE(LEFT(C10,1))<=1,AND(D10="No",E10="No")),"✗ Not Ready","⚠ Weak"))))) | G10: =IF(OR(C10="",C10="N/A"),"", VALUE(LEFT(C10,1))*(IF(D10="Yes",0.5,IF(D10="Partial",0.25,0))+IF(E10="Yes",0.5,IF(E10="Partial",0.25,0))))
B11: Emission calculation methodology | F11: =IF(OR(C11="",C11="N/A"),"", IF(AND(VALUE(LEFT(C11,1))>=3,D11="Yes",E11="Yes"),"✓ Ready", IF(AND(VALUE(LEFT(C11,1))>=3,OR(D11="Yes",E11="Yes")),"⚠ Likely", IF(AND(VALUE(LEFT(C11,1))>=2,D11="Yes",E11="Yes"),"⚠ Partial", IF(OR(VALUE(LEFT(C11,1))<=1,AND(D11="No",E11="No")),"✗ Not Ready","⚠ Weak"))))) | G11: =IF(OR(C11="",C11="N/A"),"", VALUE(LEFT(C11,1))*(IF(D11="Yes",0.5,IF(D11="Partial",0.25,0))+IF(E11="Yes",0.5,IF(E11="Partial",0.25,0))))
B12: 2. ENERGY CONSUMPTION
B13: Total energy use by source (electricity, fuel) | F13: =IF(OR(C13="",C13="N/A"),"", IF(AND(VALUE(LEFT(C13,1))>=3,D13="Yes",E13="Yes"),"✓ Ready", IF(AND(VALUE(LEFT(C13,1))>=3,OR(D13="Yes",E13="Yes")),"⚠ Likely", IF(AND(VALUE(LEFT(C13,1))>=2,D13="Yes",E13="Yes"),"⚠ Partial", IF(OR(VALUE(LEFT(C13,1))<=1,AND(D13="No",E13="No")),"✗ Not Ready","⚠ Weak"))))) | G13: =IF(OR(C13="",C13="N/A"),"", VALUE(LEFT(C13,1))*(IF(D13="Yes",0.5,IF(D13="Partial",0.25,0))+IF(E13="Yes",0.5,IF(E13="Partial",0.25,0))))
B14: Renewable vs non-renewable breakdown | F14: =IF(OR(C14="",C14="N/A"),"", IF(AND(VALUE(LEFT(C14,1))>=3,D14="Yes",E14="Yes"),"✓ Ready", IF(AND(VALUE(LEFT(C14,1))>=3,OR(D14="Yes",E14="Yes")),"⚠ Likely", IF(AND(VALUE(LEFT(C14,1))>=2,D14="Yes",E14="Yes"),"⚠ Partial", IF(OR(VALUE(LEFT(C14,1))<=1,AND(D14="No",E14="No")),"✗ Not Ready","⚠ Weak"))))) | G14: =IF(OR(C14="",C14="N/A"),"", VALUE(LEFT(C14,1))*(IF(D14="Yes",0.5,IF(D14="Partial",0.25,0))+IF(E14="Yes",0.5,IF(E14="Partial",0.25,0))))
B15: Energy intensity metrics (per unit output) | F15: =IF(OR(C15="",C15="N/A"),"", IF(AND(VALUE(LEFT(C15,1))>=3,D15="Yes",E15="Yes"),"✓ Ready", IF(AND(VALUE(LEFT(C15,1))>=3,OR(D15="Yes",E15="Yes")),"⚠ Likely", IF(AND(VALUE(LEFT(C15,1))>=2,D15="Yes",E15="Yes"),"⚠ Partial", IF(OR(VALUE(LEFT(C15,1))<=1,AND(D15="No",E15="No")),"✗ Not Ready","⚠ Weak"))))) | G15: =IF(OR(C15="",C15="N/A"),"", VALUE(LEFT(C15,1))*(IF(D15="Yes",0.5,IF(D15="Partial",0.25,0))+IF(E15="Yes",0.5,IF(E15="Partial",0.25,0))))
B16: Historical trend data (12+ months) | F16: =IF(OR(C16="",C16="N/A"),"", IF(AND(VALUE(LEFT(C16,1))>=3,D16="Yes",E16="Yes"),"✓ Ready", IF(AND(VALUE(LEFT(C16,1))>=3,OR(D16="Yes",E16="Yes")),"⚠ Likely", IF(AND(VALUE(LEFT(C16,1))>=2,D16="Yes",E16="Yes"),"⚠ Partial", IF(OR(VALUE(LEFT(C16,1))<=1,AND(D16="No",E16="No")),"✗ Not Ready","⚠ Weak"))))) | G16: =IF(OR(C16="",C16="N/A"),"", VALUE(LEFT(C16,1))*(IF(D16="Yes",0.5,IF(D16="Partial",0.25,0))+IF(E16="Yes",0.5,IF(E16="Partial",0.25,0))))
B17: 3. WATER USE
B18: Water consumption by source | F18: =IF(OR(C18="",C18="N/A"),"", IF(AND(VALUE(LEFT(C18,1))>=3,D18="Yes",E18="Yes"),"✓ Ready", IF(AND(VALUE(LEFT(C18,1))>=3,OR(D18="Yes",E18="Yes")),"⚠ Likely", IF(AND(VALUE(LEFT(C18,1))>=2,D18="Yes",E18="Yes"),"⚠ Partial", IF(OR(VALUE(LEFT(C18,1))<=1,AND(D18="No",E18="No")),"✗ Not Ready","⚠ Weak"))))) | G18: =IF(OR(C18="",C18="N/A"),"", VALUE(LEFT(C18,1))*(IF(D18="Yes",0.5,IF(D18="Partial",0.25,0))+IF(E18="Yes",0.5,IF(E18="Partial",0.25,0))))
B19: Process-level allocation | F19: =IF(OR(C19="",C19="N/A"),"", IF(AND(VALUE(LEFT(C19,1))>=3,D19="Yes",E19="Yes"),"✓ Ready", IF(AND(VALUE(LEFT(C19,1))>=3,OR(D19="Yes",E19="Yes")),"⚠ Likely", IF(AND(VALUE(LEFT(C19,1))>=2,D19="Yes",E19="Yes"),"⚠ Partial", IF(OR(VALUE(LEFT(C19,1))<=1,AND(D19="No",E19="No")),"✗ Not Ready","⚠ Weak"))))) | G19: =IF(OR(C19="",C19="N/A"),"", VALUE(LEFT(C19,1))*(IF(D19="Yes",0.5,IF(D19="Partial",0.25,0))+IF(E19="Yes",0.5,IF(E19="Partial",0.25,0))))
B20: Water intensity metrics | F20: =IF(OR(C20="",C20="N/A"),"", IF(AND(VALUE(LEFT(C20,1))>=3,D20="Yes",E20="Yes"),"✓ Ready", IF(AND(VALUE(LEFT(C20,1))>=3,OR(D20="Yes",E20="Yes")),"⚠ Likely", IF(AND(VALUE(LEFT(C20,1))>=2,D20="Yes",E20="Yes"),"⚠ Partial", IF(OR(VALUE(LEFT(C20,1))<=1,AND(D20="No",E20="No")),"✗ Not Ready","⚠ Weak"))))) | G20: =IF(OR(C20="",C20="N/A"),"", VALUE(LEFT(C20,1))*(IF(D20="Yes",0.5,IF(D20="Partial",0.25,0))+IF(E20="Yes",0.5,IF(E20="Partial",0.25,0))))
B21: 4. WASTE MANAGEMENT
B22: Waste generation by stream | F22: =IF(OR(C22="",C22="N/A"),"", IF(AND(VALUE(LEFT(C22,1))>=3,D22="Yes",E22="Yes"),"✓ Ready", IF(AND(VALUE(LEFT(C22,1))>=3,OR(D22="Yes",E22="Yes")),"⚠ Likely", IF(AND(VALUE(LEFT(C22,1))>=2,D22="Yes",E22="Yes"),"⚠ Partial", IF(OR(VALUE(LEFT(C22,1))<=1,AND(D22="No",E22="No")),"✗ Not Ready","⚠ Weak"))))) | G22: =IF(OR(C22="",C22="N/A"),"", VALUE(LEFT(C22,1))*(IF(D22="Yes",0.5,IF(D22="Partial",0.25,0))+IF(E22="Yes",0.5,IF(E22="Partial",0.25,0))))
B23: Diversion/recycling rates | F23: =IF(OR(C23="",C23="N/A"),"", IF(AND(VALUE(LEFT(C23,1))>=3,D23="Yes",E23="Yes"),"✓ Ready", IF(AND(VALUE(LEFT(C23,1))>=3,OR(D23="Yes",E23="Yes")),"⚠ Likely", IF(AND(VALUE(LEFT(C23,1))>=2,D23="Yes",E23="Yes"),"⚠ Partial", IF(OR(VALUE(LEFT(C23,1))<=1,AND(D23="No",E23="No")),"✗ Not Ready","⚠ Weak"))))) | G23: =IF(OR(C23="",C23="N/A"),"", VALUE(LEFT(C23,1))*(IF(D23="Yes",0.5,IF(D23="Partial",0.25,0))+IF(E23="Yes",0.5,IF(E23="Partial",0.25,0))))
B24: Hazardous waste compliance | F24: =IF(OR(C24="",C24="N/A"),"", IF(AND(VALUE(LEFT(C24,1))>=3,D24="Yes",E24="Yes"),"✓ Ready", IF(AND(VALUE(LEFT(C24,1))>=3,OR(D24="Yes",E24="Yes")),"⚠ Likely", IF(AND(VALUE(LEFT(C24,1))>=2,D24="Yes",E24="Yes"),"⚠ Partial", IF(OR(VALUE(LEFT(C24,1))<=1,AND(D24="No",E24="No")),"✗ Not Ready","⚠ Weak"))))) | G24: =IF(OR(C24="",C24="N/A"),"", VALUE(LEFT(C24,1))*(IF(D24="Yes",0.5,IF(D24="Partial",0.25,0))+IF(E24="Yes",0.5,IF(E24="Partial",0.25,0))))
B25: 5. SUSTAINABLE SOURCING
B26: Certified/sustainable input usage | F26: =IF(OR(C26="",C26="N/A"),"", IF(AND(VALUE(LEFT(C26,1))>=3,D26="Yes",E26="Yes"),"✓ Ready", IF(AND(VALUE(LEFT(C26,1))>=3,OR(D26="Yes",E26="Yes")),"⚠ Likely", IF(AND(VALUE(LEFT(C26,1))>=2,D26="Yes",E26="Yes"),"⚠ Partial", IF(OR(VALUE(LEFT(C26,1))<=1,AND(D26="No",E26="No")),"✗ Not Ready","⚠ Weak"))))) | G26: =IF(OR(C26="",C26="N/A"),"", VALUE(LEFT(C26,1))*(IF(D26="Yes",0.5,IF(D26="Partial",0.25,0))+IF(E26="Yes",0.5,IF(E26="Partial",0.25,0))))
B27: Supply chain traceability | F27: =IF(OR(C27="",C27="N/A"),"", IF(AND(VALUE(LEFT(C27,1))>=3,D27="Yes",E27="Yes"),"✓ Ready", IF(AND(VALUE(LEFT(C27,1))>=3,OR(D27="Yes",E27="Yes")),"⚠ Likely", IF(AND(VALUE(LEFT(C27,1))>=2,D27="Yes",E27="Yes"),"⚠ Partial", IF(OR(VALUE(LEFT(C27,1))<=1,AND(D27="No",E27="No")),"✗ Not Ready","⚠ Weak"))))) | G27: =IF(OR(C27="",C27="N/A"),"", VALUE(LEFT(C27,1))*(IF(D27="Yes",0.5,IF(D27="Partial",0.25,0))+IF(E27="Yes",0.5,IF(E27="Partial",0.25,0))))
B28: Supplier sustainability requirements | F28: =IF(OR(C28="",C28="N/A"),"", IF(AND(VALUE(LEFT(C28,1))>=3,D28="Yes",E28="Yes"),"✓ Ready", IF(AND(VALUE(LEFT(C28,1))>=3,OR(D28="Yes",E28="Yes")),"⚠ Likely", IF(AND(VALUE(LEFT(C28,1))>=2,D28="Yes",E28="Yes"),"⚠ Partial", IF(OR(VALUE(LEFT(C28,1))<=1,AND(D28="No",E28="No")),"✗ Not Ready","⚠ Weak"))))) | G28: =IF(OR(C28="",C28="N/A"),"", VALUE(LEFT(C28,1))*(IF(D28="Yes",0.5,IF(D28="Partial",0.25,0))+IF(E28="Yes",0.5,IF(E28="Partial",0.25,0))))
B29: 6. BIODIVERSITY & LAND USE
B30: Operational land area breakdown | F30: =IF(OR(C30="",C30="N/A"),"", IF(AND(VALUE(LEFT(C30,1))>=3,D30="Yes",E30="Yes"),"✓ Ready", IF(AND(VALUE(LEFT(C30,1))>=3,OR(D30="Yes",E30="Yes")),"⚠ Likely", IF(AND(VALUE(LEFT(C30,1))>=2,D30="Yes",E30="Yes"),"⚠ Partial", IF(OR(VALUE(LEFT(C30,1))<=1,AND(D30="No",E30="No")),"✗ Not Ready","⚠ Weak"))))) | G30: =IF(OR(C30="",C30="N/A"),"", VALUE(LEFT(C30,1))*(IF(D30="Yes",0.5,IF(D30="Partial",0.25,0))+IF(E30="Yes",0.5,IF(E30="Partial",0.25,0))))
B31: Conservation/biodiversity measures | F31: =IF(OR(C31="",C31="N/A"),"", IF(AND(VALUE(LEFT(C31,1))>=3,D31="Yes",E31="Yes"),"✓ Ready", IF(AND(VALUE(LEFT(C31,1))>=3,OR(D31="Yes",E31="Yes")),"⚠ Likely", IF(AND(VALUE(LEFT(C31,1))>=2,D31="Yes",E31="Yes"),"⚠ Partial", IF(OR(VALUE(LEFT(C31,1))<=1,AND(D31="No",E31="No")),"✗ Not Ready","⚠ Weak"))))) | G31: =IF(OR(C31="",C31="N/A"),"", VALUE(LEFT(C31,1))*(IF(D31="Yes",0.5,IF(D31="Partial",0.25,0))+IF(E31="Yes",0.5,IF(E31="Partial",0.25,0))))
B32: Soil health monitoring (if applicable) | F32: =IF(OR(C32="",C32="N/A"),"", IF(AND(VALUE(LEFT(C32,1))>=3,D32="Yes",E32="Yes"),"✓ Ready", IF(AND(VALUE(LEFT(C32,1))>=3,OR(D32="Yes",E32="Yes")),"⚠ Likely", IF(AND(VALUE(LEFT(C32,1))>=2,D32="Yes",E32="Yes"),"⚠ Partial", IF(OR(VALUE(LEFT(C32,1))<=1,AND(D32="No",E32="No")),"✗ Not Ready","⚠ Weak"))))) | G32: =IF(OR(C32="",C32="N/A"),"", VALUE(LEFT(C32,1))*(IF(D32="Yes",0.5,IF(D32="Partial",0.25,0))+IF(E32="Yes",0.5,IF(E32="Partial",0.25,0))))
B33: 7. CHEMICAL MANAGEMENT
B34: Application tracking | F34: =IF(OR(C34="",C34="N/A"),"", IF(AND(VALUE(LEFT(C34,1))>=3,D34="Yes",E34="Yes"),"✓ Ready", IF(AND(VALUE(LEFT(C34,1))>=3,OR(D34="Yes",E34="Yes")),"⚠ Likely", IF(AND(VALUE(LEFT(C34,1))>=2,D34="Yes",E34="Yes"),"⚠ Partial", IF(OR(VALUE(LEFT(C34,1))<=1,AND(D34="No",E34="No")),"✗ Not Ready","⚠ Weak"))))) | G34: =IF(OR(C34="",C34="N/A"),"", VALUE(LEFT(C34,1))*(IF(D34="Yes",0.5,IF(D34="Partial",0.25,0))+IF(E34="Yes",0.5,IF(E34="Partial",0.25,0))))
B35: Storage and handling compliance | F35: =IF(OR(C35="",C35="N/A"),"", IF(AND(VALUE(LEFT(C35,1))>=3,D35="Yes",E35="Yes"),"✓ Ready", IF(AND(VALUE(LEFT(C35,1))>=3,OR(D35="Yes",E35="Yes")),"⚠ Likely", IF(AND(VALUE(LEFT(C35,1))>=2,D35="Yes",E35="Yes"),"⚠ Partial", IF(OR(VALUE(LEFT(C35,1))<=1,AND(D35="No",E35="No")),"✗ Not Ready","⚠ Weak"))))) | G35: =IF(OR(C35="",C35="N/A"),"", VALUE(LEFT(C35,1))*(IF(D35="Yes",0.5,IF(D35="Partial",0.25,0))+IF(E35="Yes",0.5,IF(E35="Partial",0.25,0))))
B36: Reduction plans | F36: =IF(OR(C36="",C36="N/A"),"", IF(AND(VALUE(LEFT(C36,1))>=3,D36="Yes",E36="Yes"),"✓ Ready", IF(AND(VALUE(LEFT(C36,1))>=3,OR(D36="Yes",E36="Yes")),"⚠ Likely", IF(AND(VALUE(LEFT(C36,1))>=2,D36="Yes",E36="Yes"),"⚠ Partial", IF(OR(VALUE(LEFT(C36,1))<=1,AND(D36="No",E36="No")),"✗ Not Ready","⚠ Weak"))))) | G36: =IF(OR(C36="",C36="N/A"),"", VALUE(LEFT(C36,1))*(IF(D36="Yes",0.5,IF(D36="Partial",0.25,0))+IF(E36="Yes",0.5,IF(E36="Partial",0.25,0))))
B37: 8. ANIMAL WELFARE (if applicable)
B38: Housing/living conditions documented | F38: =IF(OR(C38="",C38="N/A"),"", IF(AND(VALUE(LEFT(C38,1))>=3,D38="Yes",E38="Yes"),"✓ Ready", IF(AND(VALUE(LEFT(C38,1))>=3,OR(D38="Yes",E38="Yes")),"⚠ Likely", IF(AND(VALUE(LEFT(C38,1))>=2,D38="Yes",E38="Yes"),"⚠ Partial", IF(OR(VALUE(LEFT(C38,1))<=1,AND(D38="No",E38="No")),"✗ Not Ready","⚠ Weak"))))) | G38: =IF(OR(C38="",C38="N/A"),"", VALUE(LEFT(C38,1))*(IF(D38="Yes",0.5,IF(D38="Partial",0.25,0))+IF(E38="Yes",0.5,IF(E38="Partial",0.25,0))))
B39: Health protocols | F39: =IF(OR(C39="",C39="N/A"),"", IF(AND(VALUE(LEFT(C39,1))>=3,D39="Yes",E39="Yes"),"✓ Ready", IF(AND(VALUE(LEFT(C39,1))>=3,OR(D39="Yes",E39="Yes")),"⚠ Likely", IF(AND(VALUE(LEFT(C39,1))>=2,D39="Yes",E39="Yes"),"⚠ Partial", IF(OR(VALUE(LEFT(C39,1))<=1,AND(D39="No",E39="No")),"✗ Not Ready","⚠ Weak"))))) | G39: =IF(OR(C39="",C39="N/A"),"", VALUE(LEFT(C39,1))*(IF(D39="Yes",0.5,IF(D39="Partial",0.25,0))+IF(E39="Yes",0.5,IF(E39="Partial",0.25,0))))
B40: Antibiotic use policy | F40: =IF(OR(C40="",C40="N/A"),"", IF(AND(VALUE(LEFT(C40,1))>=3,D40="Yes",E40="Yes"),"✓ Ready", IF(AND(VALUE(LEFT(C40,1))>=3,OR(D40="Yes",E40="Yes")),"⚠ Likely", IF(AND(VALUE(LEFT(C40,1))>=2,D40="Yes",E40="Yes"),"⚠ Partial", IF(OR(VALUE(LEFT(C40,1))<=1,AND(D40="No",E40="No")),"✗ Not Ready","⚠ Weak"))))) | G40: =IF(OR(C40="",C40="N/A"),"", VALUE(LEFT(C40,1))*(IF(D40="Yes",0.5,IF(D40="Partial",0.25,0))+IF(E40="Yes",0.5,IF(E40="Partial",0.25,0))))
B41: 9. LABOR & SOCIAL PRACTICES
B42: Fair labor compliance | F42: =IF(OR(C42="",C42="N/A"),"", IF(AND(VALUE(LEFT(C42,1))>=3,D42="Yes",E42="Yes"),"✓ Ready", IF(AND(VALUE(LEFT(C42,1))>=3,OR(D42="Yes",E42="Yes")),"⚠ Likely", IF(AND(VALUE(LEFT(C42,1))>=2,D42="Yes",E42="Yes"),"⚠ Partial", IF(OR(VALUE(LEFT(C42,1))<=1,AND(D42="No",E42="No")),"✗ Not Ready","⚠ Weak"))))) | G42: =IF(OR(C42="",C42="N/A"),"", VALUE(LEFT(C42,1))*(IF(D42="Yes",0.5,IF(D42="Partial",0.25,0))+IF(E42="Yes",0.5,IF(E42="Partial",0.25,0))))
...

Sheet Results
B2: YOUR READINESS RESULTS
B4: OVERALL READINESS SCORE
C5: =Assessment!C62
B7: Interpretation: | C7: =IF(C5>=0.8,"Well prepared for buyer requests",IF(C5>=0.6,"Moderate readiness - key gaps exist",IF(C5>=0.4,"Significant gaps - prioritize improvement","Major capability building needed")))
B10: CATEGORY BREAKDOWN
B11: Category | C11: Avg Score | D11: Status
B12: Carbon Footprint Data | C12: =IF(COUNT(Assessment!G8:G11)=0,"N/A",AVERAGE(Assessment!G8:G11)/5) | D12: =IF(C12="N/A","—",IF(C12>=0.7,"✓ OK",IF(C12>=0.4,"⚠ GAP","✗ CRITICAL")))
B13: Energy Consumption | C13: =IF(COUNT(Assessment!G13:G16)=0,"N/A",AVERAGE(Assessment!G13:G16)/5) | D13: =IF(C13="N/A","—",IF(C13>=0.7,"✓ OK",IF(C13>=0.4,"⚠ GAP","✗ CRITICAL")))
B14: Water Use | C14: =IF(COUNT(Assessment!G18:G20)=0,"N/A",AVERAGE(Assessment!G18:G20)/5) | D14: =IF(C14="N/A","—",IF(C14>=0.7,"✓ OK",IF(C14>=0.4,"⚠ GAP","✗ CRITICAL")))
B15: Waste Management | C15: =IF(COUNT(Assessment!G22:G24)=0,"N/A",AVERAGE(Assessment!G22:G24)/5) | D15: =IF(C15="N/A","—",IF(C15>=0.7,"✓ OK",IF(C15>=0.4,"⚠ GAP","✗ CRITICAL")))
B16: Sustainable Sourcing | C16: =IF(COUNT(Assessment!G26:G28)=0,"N/A",AVERAGE(Assessment!G26:G28)/5) | D16: =IF(C16="N/A","—",IF(C16>=0.7,"✓ OK",IF(C16>=0.4,"⚠ GAP","✗ CRITICAL")))
B17: Biodiversity & Land Use | C17: =IF(COUNT(Assessment!G30:G32)=0,"N/A",AVERAGE(Assessment!G30:G32)/5) | D17: =IF(C17="N/A","—",IF(C17>=0.7,"✓ OK",IF(C17>=0.4,"⚠ GAP","✗ CRITICAL")))
B18: Chemical Management | C18: =IF(COUNT(Assessment!G34:G36)=0,"N/A",AVERAGE(Assessment!G34:G36)/5) | D18: =IF(C18="N/A","—",IF(C18>=0.7,"✓ OK",IF(C18>=0.4,"⚠ GAP","✗ CRITICAL")))
B19: Animal Welfare | C19: =IF(COUNT(Assessment!G38:G40)=0,"N/A",AVERAGE(Assessment!G38:G40)/5) | D19: =IF(C19="N/A","—",IF(C19>=0.7,"✓ OK",IF(C19>=0.4,"⚠ GAP","✗ CRITICAL")))
B20: Labor & Social Practices | C20: =IF(COUNT(Assessment!G42:G44)=0,"N/A",AVERAGE(Assessment!G42:G44)/5) | D20: =IF(C20="N/A","—",IF(C20>=0.7,"✓ OK",IF(C20>=0.4,"⚠ GAP","✗ CRITICAL")))
B21: Climate Adaptation | C21: =IF(COUNT(Assessment!G46:G48)=0,"N/A",AVERAGE(Assessment!G46:G48)/5) | D21: =IF(C21="N/A","—",IF(C21>=0.7,"✓ OK",IF(C21>=0.4,"⚠ GAP","✗ CRITICAL")))
B22: Certifications & Standards | C22: =IF(COUNT(Assessment!G50:G52)=0,"N/A",AVERAGE(Assessment!G50:G52)/5) | D22: =IF(C22="N/A","—",IF(C22>=0.7,"✓ OK",IF(C22>=0.4,"⚠ GAP","✗ CRITICAL")))
B23: Sustainability Governance | C23: =IF(COUNT(Assessment!G54:G56)=0,"N/A",AVERAGE(Assessment!G54:G56)/5) | D23: =IF(C23="N/A","—",IF(C23>=0.7,"✓ OK",IF(C23>=0.4,"⚠ GAP","✗ CRITICAL")))
B26: RESPONSE READINESS SUMMARY
B27: ✓ Ready items: | C27: =COUNTIF(Assessment!F7:F56,"✓ Ready")
B28: ⚠ Likely/Partial/Weak items: | C28: =COUNTIF(Assessment!F7:F56,"⚠*")
B29: ✗ Not Ready items: | C29: =COUNTIF(Assessment!F7:F56,"✗ Not Ready")
B32: NEXT STEPS
B34: 1. Use the Gap Analysis Prioritization Matrix to decide what to fix first
B35: 2. Use the Response Templates when buyers ask questions
B36: 3. Focus on items marked '✗ Not Ready' and '✗ CRITICAL' categories
B38: Need to BUILD the data systems? Get the Complete Baseline System (€99)

Sheet Gap Analysis
B2: GAP ANALYSIS
B3: Review items where Response Ready = ✗ Not Ready or ⚠ Weak
B5: Category | C5: Response Status | D5: Action Needed
B7: To identify your gaps:
B8: 1. Go to the Assessment tab
B9: 2. Look at the 'Response Ready' column
B10: 3. Items showing '✗ Not Ready' need attention
B11: 4. Items showing '⚠ Weak' could be improved
B13: Common fixes:
B14: • Not Ready due to low confidence → Start collecting/measuring this data
B15: • Not Ready due to no methodology → Document how you calculate/measure
B16: • Not Ready due to no records → Organize your source files (invoices, logs)
B18: Use the Gap Analysis Prioritization Matrix to decide which gaps to close first.

Sheet Config
A1: Data Confidence | D1: Yes/Partial/No
A2: 0 - No data | B2: 0 | D2: Yes | E2: 1
A3: 1 - Rough guess | B3: 1 | D3: Partial | E3: 0.5
A4: 2 - Partial data | B4: 2 | D4: No | E4: 0
A5: 3 - Complete, unverified | B5: 3
A6: 4 - Complete, internally verified | B6: 4
A7: 5 - Complete, third-party verified | B7: 5
A8: N/A - Not applicable | B8: -1
